<?xml version="1.0"?>
<!-- Simple Humanoid Robot URDF -->
<robot name="simple_humanoid">
  <!-- Torso (base link) -->
  <link name="base_link">
    <visual>
      <geometry>
        <box size="0.2 0.2 0.6"/>
      </geometry>
      <material name="light_grey">
        <color rgba="0.7 0.7 0.7 1"/>
      </material>
    </visual>
    <collision>
      <geometry>
        <box size="0.2 0.2 0.6"/>
      </geometry>
    </collision>
    <inertial>
      <mass value="5"/>
      <inertia ixx="0.1" ixy="0" ixz="0" iyy="0.1" iyz="0" izz="0.1"/>
    </inertial>
  </link>

  <!-- Head -->
  <link name="head">
    <visual>
      <geometry>
        <sphere radius="0.1"/>
      </geometry>
      <material name="skin">
        <color rgba="0.8 0.6 0.4 1"/>
      </material>
    </visual>
    <collision>
      <geometry>
        <sphere radius="0.1"/>
      </geometry>
    </collision>
    <inertial>
      <mass value="1"/>
      <inertia ixx="0.004" ixy="0" ixz="0" iyy="0.004" iyz="0" izz="0.004"/>
    </inertial>
  </link>

  <joint name="neck_joint" type="revolute">
    <parent link="base_link"/>
    <child link="head"/>
    <origin xyz="0 0 0.4" rpy="0 0 0"/>
    <axis xyz="0 1 0"/>
    <limit lower="-0.5" upper="0.5" effort="10" velocity="1"/>
  </joint>

  <!-- Left Arm -->
  <link name="left_upper_arm">
    <visual>
      <geometry>
        <cylinder length="0.3" radius="0.05"/>
      </geometry>
      <material name="arm_color">
        <color rgba="0.5 0.5 0.5 1"/>
      </material>
    </visual>
    <collision>
      <geometry>
        <cylinder length="0.3" radius="0.05"/>
      </geometry>
    </collision>
    <inertial>
      <mass value="0.5"/>
      <inertia ixx="0.001" ixy="0" ixz="0" iyy="0.001" iyz="0" izz="0.001"/>
    </inertial>
  </link>

  <link name="left_lower_arm">
    <visual>
      <geometry>
        <cylinder length="0.3" radius="0.04"/>
      </geometry>
      <material name="arm_color">
        <color rgba="0.5 0.5 0.5 1"/>
      </material>
    </visual>
    <collision>
      <geometry>
        <cylinder length="0.3" radius="0.04"/>
      </geometry>
    </collision>
    <inertial>
      <mass value="0.3"/>
      <inertia ixx="0.0005" ixy="0" ixz="0" iyy="0.0005" iyz="0" izz="0.0005"/>
    </inertial>
  </link>

  <joint name="left_shoulder_joint" type="revolute">
    <parent link="base_link"/>
    <child link="left_upper_arm"/>
    <origin xyz="0.15 0 0.1" rpy="0 0 0"/>
    <axis xyz="0 1 0"/>
    <limit lower="-1.57" upper="1.57" effort="5" velocity="1"/>
  </joint>

  <joint name="left_elbow_joint" type="revolute">
    <parent link="left_upper_arm"/>
    <child link="left_lower_arm"/>
    <origin xyz="0 0 -0.3" rpy="0 0 0"/>
    <axis xyz="0 1 0"/>
    <limit lower="-1.57" upper="1.57" effort="5" velocity="1"/>
  </joint>

  <!-- Right Arm -->
  <link name="right_upper_arm">
    <visual>
      <geometry>
        <cylinder length="0.3" radius="0.05"/>
      </geometry>
      <material name="arm_color">
        <color rgba="0.5 0.5 0.5 1"/>
      </material>
    </visual>
    <collision>
      <geometry>
        <cylinder length="0.3" radius="0.05"/>
      </geometry>
    </collision>
    <inertial>
      <mass value="0.5"/>
      <inertia ixx="0.001" ixy="0" ixz="0" iyy="0.001" iyz="0" izz="0.001"/>
    </inertial>
  </link>

  <link name="right_lower_arm">
    <visual>
      <geometry>
        <cylinder length="0.3" radius="0.04"/>
      </geometry>
      <material name="arm_color">
        <color rgba="0.5 0.5 0.5 1"/>
      </material>
    </visual>
    <collision>
      <geometry>
        <cylinder length="0.3" radius="0.04"/>
      </geometry>
    </collision>
    <inertial>
      <mass value="0.3"/>
      <inertia ixx="0.0005" ixy="0" ixz="0" iyy="0.0005" iyz="0" izz="0.0005"/>
    </inertial>
  </link>

  <joint name="right_shoulder_joint" type="revolute">
    <parent link="base_link"/>
    <child link="right_upper_arm"/>
    <origin xyz="-0.15 0 0.1" rpy="0 0 0"/>
    <axis xyz="0 1 0"/>
    <limit lower="-1.57" upper="1.57" effort="5" velocity="1"/>
  </joint>

  <joint name="right_elbow_joint" type="revolute">
    <parent link="right_upper_arm"/>
    <child link="right_lower_arm"/>
    <origin xyz="0 0 -0.3" rpy="0 0 0"/>
    <axis xyz="0 1 0"/>
    <limit lower="-1.57" upper="1.57" effort="5" velocity="1"/>
  </joint>

  <!-- Left Leg -->
  <link name="left_upper_leg">
    <visual>
      <geometry>
        <cylinder length="0.4" radius="0.06"/>
      </geometry>
      <material name="leg_color">
        <color rgba="0.4 0.4 0.4 1"/>
      </material>
    </visual>
    <collision>
      <geometry>
        <cylinder length="0.4" radius="0.06"/>
      </geometry>
    </collision>
    <inertial>
      <mass value="1"/>
      <inertia ixx="0.002" ixy="0" ixz="0" iyy="0.002" iyz="0" izz="0.002"/>
    </inertial>
  </link>

  <link name="left_lower_leg">
    <visual>
      <geometry>
        <cylinder length="0.4" radius="0.05"/>
      </geometry>
      <material name="leg_color">
        <color rgba="0.4 0.4 0.4 1"/>
      </material>
    </visual>
    <collision>
      <geometry>
        <cylinder length="0.4" radius="0.05"/>
      </geometry>
    </collision>
    <inertial>
      <mass value="0.7"/>
      <inertia ixx="0.0015" ixy="0" ixz="0" iyy="0.0015" iyz="0" izz="0.0015"/>
    </inertial>
  </link>

  <link name="left_foot">
    <visual>
      <geometry>
        <box size="0.15 0.08 0.05"/>
      </geometry>
      <material name="foot_color">
        <color rgba="0.2 0.2 0.2 1"/>
      </material>
    </visual>
    <collision>
      <geometry>
        <box size="0.15 0.08 0.05"/>
      </geometry>
    </collision>
    <inertial>
      <mass value="0.2"/>
      <inertia ixx="0.0001" ixy="0" ixz="0" iyy="0.0001" iyz="0" izz="0.0001"/>
    </inertial>
  </link>

  <joint name="left_hip_joint" type="revolute">
    <parent link="base_link"/>
    <child link="left_upper_leg"/>
    <origin xyz="0.08 0 -0.3" rpy="0 0 0"/>
    <axis xyz="0 1 0"/>
    <limit lower="-1.57" upper="1.57" effort="10" velocity="1"/>
  </joint>

  <joint name="left_knee_joint" type="revolute">
    <parent link="left_upper_leg"/>
    <child link="left_lower_leg"/>
    <origin xyz="0 0 -0.4" rpy="0 0 0"/>
    <axis xyz="0 1 0"/>
    <limit lower="0" upper="1.57" effort="10" velocity="1"/>
  </joint>

  <joint name="left_ankle_joint" type="revolute">
    <parent link="left_lower_leg"/>
    <child link="left_foot"/>
    <origin xyz="0 0 -0.4" rpy="0 0 0"/>
    <axis xyz="0 1 0"/>
    <limit lower="-0.5" upper="0.5" effort="5" velocity="1"/>
  </joint>

  <!-- Right Leg -->
  <link name="right_upper_leg">
    <visual>
      <geometry>
        <cylinder length="0.4" radius="0.06"/>
      </geometry>
      <material name="leg_color">
        <color rgba="0.4 0.4 0.4 1"/>
      </material>
    </visual>
    <collision>
      <geometry>
        <cylinder length="0.4" radius="0.06"/>
      </geometry>
    </collision>
    <inertial>
      <mass value="1"/>
      <inertia ixx="0.002" ixy="0" ixz="0" iyy="0.002" iyz="0" izz="0.002"/>
    </inertial>
  </link>

  <link name="right_lower_leg">
    <visual>
      <geometry>
        <cylinder length="0.4" radius="0.05"/>
      </geometry>
      <material name="leg_color">
        <color rgba="0.4 0.4 0.4 1"/>
      </material>
    </visual>
    <collision>
      <geometry>
        <cylinder length="0.4" radius="0.05"/>
      </geometry>
    </collision>
    <inertial>
      <mass value="0.7"/>
      <inertia ixx="0.0015" ixy="0" ixz="0" iyy="0.0015" iyz="0" izz="0.0015"/>
    </inertial>
  </link>

  <link name="right_foot">
    <visual>
      <geometry>
        <box size="0.15 0.08 0.05"/>
      </geometry>
      <material name="foot_color">
        <color rgba="0.2 0.2 0.2 1"/>
      </material>
    </visual>
    <collision>
      <geometry>
        <box size="0.15 0.08 0.05"/>
      </geometry>
    </collision>
    <inertial>
      <mass value="0.2"/>
      <inertia ixx="0.0001" ixy="0" ixz="0" iyy="0.0001" iyz="0" izz="0.0001"/>
    </inertial>
  </link>

  <joint name="right_hip_joint" type="revolute">
    <parent link="base_link"/>
    <child link="right_upper_leg"/>
    <origin xyz="-0.08 0 -0.3" rpy="0 0 0"/>
    <axis xyz="0 1 0"/>
    <limit lower="-1.57" upper="1.57" effort="10" velocity="1"/>
  </joint>

  <joint name="right_knee_joint" type="revolute">
    <parent link="right_upper_leg"/>
    <child link="right_lower_leg"/>
    <origin xyz="0 0 -0.4" rpy="0 0 0"/>
    <axis xyz="0 1 0"/>
    <limit lower="0" upper="1.57" effort="10" velocity="1"/>
  </joint>

  <joint name="right_ankle_joint" type="revolute">
    <parent link="right_lower_leg"/>
    <child link="right_foot"/>
    <origin xyz="0 0 -0.4" rpy="0 0 0"/>
    <axis xyz="0 1 0"/>
    <limit lower="-0.5" upper="0.5" effort="5" velocity="1"/>
  </joint>
</robot>